test_anagram (__main__.TestExercice) ... ERROR
test_doubles (__main__.TestExercice) ... ERROR
test_grades (__main__.TestExercice) ... FAIL
test_histogram (__main__.TestExercice) ... FAIL
test_order (__main__.TestExercice) ... ERROR

======================================================================
ERROR: test_anagram (__main__.TestExercice)
----------------------------------------------------------------------
Traceback (most recent call last):
  File "test_exercice.py", line 35, in test_anagram
    output = [exercice.anagrams(v) for v in words]
  File "test_exercice.py", line 35, in <listcomp>
    output = [exercice.anagrams(v) for v in words]
  File "/home/runner/work/c01_ch6_exercices-XavierJDN/c01_ch6_exercices-XavierJDN/exercice.py", line 21, in anagrams
    if words[1][i] != words[2][len(words) - i]:
IndexError: list index out of range

======================================================================
ERROR: test_doubles (__main__.TestExercice)
----------------------------------------------------------------------
Traceback (most recent call last):
  File "test_exercice.py", line 49, in test_doubles
    output = [exercice.contains_doubles(v) for v in values]
  File "test_exercice.py", line 49, in <listcomp>
    output = [exercice.contains_doubles(v) for v in values]
  File "/home/runner/work/c01_ch6_exercices-XavierJDN/c01_ch6_exercices-XavierJDN/exercice.py", line 28, in contains_doubles
    my_set = {items}
TypeError: unhashable type: 'list'

======================================================================
ERROR: test_order (__main__.TestExercice)
----------------------------------------------------------------------
Traceback (most recent call last):
  File "test_exercice.py", line 19, in test_order
    output = [exercice.order(v) for v in values]
  File "test_exercice.py", line 19, in <listcomp>
    output = [exercice.order(v) for v in values]
  File "/home/runner/work/c01_ch6_exercices-XavierJDN/c01_ch6_exercices-XavierJDN/exercice.py", line 9, in order
    values.append(input("Entre une valeur"))
EOFError: EOF when reading a line

======================================================================
FAIL: test_grades (__main__.TestExercice)
----------------------------------------------------------------------
Traceback (most recent call last):
  File "test_exercice.py", line 69, in test_grades
    'Erreur dans les notes'
AssertionError: [{}] is not an instance of <class 'dict'> : First argument is not a dictionary

======================================================================
FAIL: test_histogram (__main__.TestExercice)
----------------------------------------------------------------------
Traceback (most recent call last):
  File "test_exercice.py", line 84, in test_histogram
    'Erreur dans les histogrammes'
AssertionError: [({}, []), ({}, [])] is not an instance of <class 'dict'> : First argument is not a dictionary

----------------------------------------------------------------------
Ran 5 tests in 0.001s

FAILED (failures=2, errors=3)
